<?xml version='1.0' encoding='UTF-8'?>
<robot name="ur5e_dg5f_left">
  <!--
    Base UR robot series xacro macro.

    NOTE this is NOT a URDF. It cannot directly be loaded by consumers
    expecting a flattened '.urdf' file. See the top-level '.xacro' for that
    (but note that .xacro must still be processed by the xacro command).

    This file models the base kinematic chain of a UR robot, which then gets
    parameterised by various configuration files to convert it into a UR3(e),
    UR5(e), UR10(e) or UR16e, etc.

    NOTE the default kinematic parameters (i.e., link lengths, frame locations,
    offsets, etc) do not correspond to any particular robot. They are defaults
    only. There WILL be non-zero offsets between the Forward Kinematics results
    in TF (i.e., robot_state_publisher) and the values reported by the Teach
    Pendant.

    For accurate (and robot-specific) transforms, the 'kinematics_parameters_file'
    parameter MUST point to a .yaml file containing the appropriate values for
    the targeted robot.

    If using the UniversalRobots/Universal_Robots_ROS_Driver, follow the steps
    described in the readme of that repository to extract the kinematic
    calibration from the controller and generate the required .yaml file.

    Main author of the migration to yaml configs Ludovic Delval.

    Contributors to previous versions (in no particular order)

     - Denis Stogl
     - Lovro Ivanov
     - Felix Messmer
     - Kelsey Hawkins
     - Wim Meeussen
     - Shaun Edwards
     - Nadia Hammoudeh Garcia
     - Dave Hershberger
     - G. vd. Hoorn
     - Philip Long
     - Dave Coleman
     - Miguel Prada
     - Mathias Luedtke
     - Marcel Schnirring
     - Felix von Drigalski
     - Felix Exner
     - Jimmy Da Silva
     - Ajit Krisshna N L
     - Muhammad Asif Rana
  -->
  <!-- create link fixed to the "world" -->
  <link name="world"/>
  <!-- links -  main serial chain -->
  <!-- base_link serves as the root of the robot's kinematic tree. It follows REP-103
        conventions (i.e., X+ forward, Y+ left, Z+ up).
        Since some kinematic solvers forbid having inertia values attached to a root link, we've
        added the base_link_inertia link that carries the visual, collision and inertia
        information.
    -->
  <link name="base_link"/>
  <link name="base_link_inertia">
    <visual>
      <origin rpy="0.0 0.0 3.141592653589793" xyz="0.0 0.0 0.0"/>
      <geometry>
        <mesh filename="meshes/ur/ur5e/visual/base.dae"/>
      </geometry>
    </visual>
    <collision>
      <origin rpy="0.0 0.0 3.141592653589793" xyz="0.0 0.0 0.0"/>
      <geometry>
        <mesh filename="meshes/ur/ur5e/collision/base.stl"/>
      </geometry>
    </collision>
    <inertial>
      <mass value="4.0"/>
      <origin rpy="0 0 0" xyz="0 0 0"/>
      <inertia ixx="0.00443333156" ixy="0.0" ixz="0.0" iyy="0.00443333156" iyz="0.0" izz="0.0072"/>
    </inertial>
  </link>
  <link name="shoulder_link">
    <visual>
      <origin rpy="0.0 0.0 3.141592653589793" xyz="0.0 0.0 0.0"/>
      <geometry>
        <mesh filename="meshes/ur/ur5e/visual/shoulder.dae"/>
      </geometry>
    </visual>
    <collision>
      <origin rpy="0.0 0.0 3.141592653589793" xyz="0.0 0.0 0.0"/>
      <geometry>
        <mesh filename="meshes/ur/ur5e/collision/shoulder.stl"/>
      </geometry>
    </collision>
    <inertial>
      <mass value="3.761"/>
      <origin rpy="1.570796326794897 0 0" xyz="0.0 -0.00193 -0.02561"/>
      <inertia ixx="0.0070021" ixy="7.3e-07" ixz="-1.053e-05" iyy="0.00648091" iyz="0.00049994" izz="0.00657286"/>
    </inertial>
  </link>
  <link name="upper_arm_link">
    <visual>
      <origin rpy="1.5707963267948966 0.0 -1.5707963267948966" xyz="0.0 0.0 0.138"/>
      <geometry>
        <mesh filename="meshes/ur/ur5e/visual/upperarm.dae"/>
      </geometry>
    </visual>
    <collision>
      <origin rpy="1.5707963267948966 0.0 -1.5707963267948966" xyz="0.0 0.0 0.138"/>
      <geometry>
        <mesh filename="meshes/ur/ur5e/collision/upperarm.stl"/>
      </geometry>
    </collision>
    <inertial>
      <mass value="8.058"/>
      <origin rpy="0 0 0" xyz="-0.2125 0.0 0.11336"/>
      <inertia ixx="0.01505885" ixy="-5.4e-05" ixz="5.63e-06" iyy="0.33388086" iyz="-1.81e-06" izz="0.33247207"/>
    </inertial>
  </link>
  <link name="forearm_link">
    <visual>
      <origin rpy="1.5707963267948966 0.0 -1.5707963267948966" xyz="0.0 0.0 0.007"/>
      <geometry>
        <mesh filename="meshes/ur/ur5e/visual/forearm.dae"/>
      </geometry>
    </visual>
    <collision>
      <origin rpy="1.5707963267948966 0.0 -1.5707963267948966" xyz="0.0 0.0 0.007"/>
      <geometry>
        <mesh filename="meshes/ur/ur5e/collision/forearm.stl"/>
      </geometry>
    </collision>
    <inertial>
      <mass value="2.846"/>
      <origin rpy="0 0 0" xyz="-0.2422 0.0 0.0265"/>
      <inertia ixx="0.00399632" ixy="-1.365e-05" ixz="0.00137272" iyy="0.07879254" iyz="-6.6e-06" izz="0.0784851"/>
    </inertial>
  </link>
  <link name="wrist_1_link">
    <visual>
      <origin rpy="1.5707963267948966 0.0 0.0" xyz="0.0 0.0 -0.127"/>
      <geometry>
        <mesh filename="meshes/ur/ur5e/visual/wrist1.dae"/>
      </geometry>
    </visual>
    <collision>
      <origin rpy="1.5707963267948966 0.0 0.0" xyz="0.0 0.0 -0.127"/>
      <geometry>
        <mesh filename="meshes/ur/ur5e/collision/wrist1.stl"/>
      </geometry>
    </collision>
    <inertial>
      <mass value="1.37"/>
      <origin rpy="1.570796326794897 0 0" xyz="0.0 -0.01634 -0.0018"/>
      <inertia ixx="0.00165491" ixy="-2.82e-06" ixz="-4.38e-06" iyy="0.00135962" iyz="0.00010157" izz="0.00126279"/>
    </inertial>
  </link>
  <link name="wrist_2_link">
    <visual>
      <origin rpy="0.0 0.0 0.0" xyz="0.0 0.0 -0.0997"/>
      <geometry>
        <mesh filename="meshes/ur/ur5e/visual/wrist2.dae"/>
      </geometry>
    </visual>
    <collision>
      <origin rpy="0.0 0.0 0.0" xyz="0.0 0.0 -0.0997"/>
      <geometry>
        <mesh filename="meshes/ur/ur5e/collision/wrist2.stl"/>
      </geometry>
    </collision>
    <inertial>
      <mass value="1.3"/>
      <origin rpy="-1.570796326794897 0 0" xyz="0.0 0.01634 -0.0018"/>
      <inertia ixx="0.00135617" ixy="-2.74e-06" ixz="4.44e-06" iyy="0.00127827" iyz="-5.048e-05" izz="0.00096614"/>
    </inertial>
  </link>
  <link name="wrist_3_link">
    <visual>
      <origin rpy="1.5707963267948966 0.0 0.0" xyz="0.0 -0.0005 -0.0989"/>
      <geometry>
        <mesh filename="meshes/ur/ur5e/visual/wrist3.dae"/>
      </geometry>
    </visual>
    <collision>
      <origin rpy="1.5707963267948966 0.0 0.0" xyz="0.0 -0.0005 -0.0989"/>
      <geometry>
        <mesh filename="meshes/ur/ur5e/collision/wrist3.stl"/>
      </geometry>
    </collision>
    <inertial>
      <mass value="0.365"/>
      <origin rpy="0 0 0" xyz="0.0 0.0 -0.001159"/>
      <inertia ixx="0.00018694" ixy="6e-08" ixz="-1.7e-07" iyy="0.00018908" iyz="-9.2e-07" izz="0.00025756"/>
    </inertial>
  </link>
  <!-- base_joint fixes base_link to the environment -->
  <joint name="base_joint" type="fixed">
    <origin rpy="0 0 0" xyz="0 0 0"/>
    <parent link="world"/>
    <child link="base_link"/>
  </joint>
  <!-- joints - main serial chain -->
  <joint name="base_link-base_link_inertia" type="fixed">
    <parent link="base_link"/>
    <child link="base_link_inertia"/>
    <!-- 'base_link' is REP-103 aligned (so X+ forward), while the internal
           frames of the robot/controller have X+ pointing backwards.
           Use the joint between 'base_link' and 'base_link_inertia' (a dummy
           link/frame) to introduce the necessary rotation over Z (of pi rad).
      -->
    <origin rpy="0 0 3.141592653589793" xyz="0 0 0"/>
  </joint>
  <joint name="shoulder_pan_joint" type="revolute">
    <parent link="base_link_inertia"/>
    <child link="shoulder_link"/>
    <origin rpy="0 0 0" xyz="0 0 0.1625"/>
    <axis xyz="0 0 1"/>
    <limit effort="150.0" lower="-6.283185307179586" upper="6.283185307179586" velocity="3.141592653589793"/>
    <dynamics damping="0" friction="0"/>
  </joint>
  <joint name="shoulder_lift_joint" type="revolute">
    <parent link="shoulder_link"/>
    <child link="upper_arm_link"/>
    <origin rpy="1.570796327 0 0" xyz="0 0 0"/>
    <axis xyz="0 0 1"/>
    <limit effort="150.0" lower="-6.283185307179586" upper="6.283185307179586" velocity="3.141592653589793"/>
    <dynamics damping="0" friction="0"/>
  </joint>
  <joint name="elbow_joint" type="revolute">
    <parent link="upper_arm_link"/>
    <child link="forearm_link"/>
    <origin rpy="0 0 0" xyz="-0.425 0 0"/>
    <axis xyz="0 0 1"/>
    <limit effort="150.0" lower="-3.141592653589793" upper="3.141592653589793" velocity="3.141592653589793"/>
    <dynamics damping="0" friction="0"/>
  </joint>
  <joint name="wrist_1_joint" type="revolute">
    <parent link="forearm_link"/>
    <child link="wrist_1_link"/>
    <origin rpy="0 0 0" xyz="-0.3922 0 0.1333"/>
    <axis xyz="0 0 1"/>
    <limit effort="28.0" lower="-6.283185307179586" upper="6.283185307179586" velocity="3.141592653589793"/>
    <dynamics damping="0" friction="0"/>
  </joint>
  <joint name="wrist_2_joint" type="revolute">
    <parent link="wrist_1_link"/>
    <child link="wrist_2_link"/>
    <origin rpy="1.570796327 0 0" xyz="0 -0.0997 -2.044881182297852e-11"/>
    <axis xyz="0 0 1"/>
    <limit effort="28.0" lower="-6.283185307179586" upper="6.283185307179586" velocity="3.141592653589793"/>
    <dynamics damping="0" friction="0"/>
  </joint>
  <joint name="wrist_3_joint" type="revolute">
    <parent link="wrist_2_link"/>
    <child link="wrist_3_link"/>
    <origin rpy="1.570796326589793 3.141592653589793 3.141592653589793" xyz="0 0.0996 -2.042830148012698e-11"/>
    <axis xyz="0 0 1"/>
    <limit effort="28.0" lower="-6.283185307179586" upper="6.283185307179586" velocity="3.141592653589793"/>
    <dynamics damping="0" friction="0"/>
  </joint>
  <link name="ft_frame"/>
  <joint name="wrist_3_link-ft_frame" type="fixed">
    <parent link="wrist_3_link"/>
    <child link="ft_frame"/>
    <origin rpy="3.141592653589793 0 0" xyz="0 0 0"/>
  </joint>
  <!-- ROS-Industrial 'base' frame - base_link to UR 'Base' Coordinates transform -->
  <link name="base"/>
  <joint name="base_link-base_fixed_joint" type="fixed">
    <!-- Note the rotation over Z of pi radians - as base_link is REP-103
           aligned (i.e., has X+ forward, Y+ left and Z+ up), this is needed
           to correctly align 'base' with the 'Base' coordinate system of
           the UR controller.
      -->
    <origin rpy="0 0 3.141592653589793" xyz="0 0 0"/>
    <parent link="base_link"/>
    <child link="base"/>
  </joint>
  <!-- ROS-Industrial 'flange' frame - attachment point for EEF models -->
  <link name="flange"/>
  <joint name="wrist_3-flange" type="fixed">
    <parent link="wrist_3_link"/>
    <child link="flange"/>
    <origin rpy="0 -1.5707963267948966 -1.5707963267948966" xyz="0 0 0"/>
  </joint>
  <!-- ROS-Industrial 'tool0' frame - all-zeros tool frame -->
  <link name="tool0"/>
  <joint name="flange-tool0" type="fixed">
    <!-- default toolframe - X+ left, Y+ up, Z+ front -->
    <origin rpy="1.5707963267948966 0 1.5707963267948966" xyz="0 0 0"/>
    <parent link="flange"/>
    <child link="tool0"/>
  </joint>
  <link name="ll_dg_mount">
    <inertial>
      <origin xyz="6.4721E-09 2.1674E-05 0.0049997" rpy="0.0 0.0 0.0"/>
      <inertia ixx="1.0999E-05" ixy="-2.1734E-12" ixz="-1.2441E-12" iyy="1.1018E-05" iyz="-4.0435E-09" izz="2.0531E-05"/>
      <mass value="0.05"/>
    </inertial>
    <visual>
      <geometry>
        <mesh filename="meshes/dg5f_left/ll_dg_mount.dae"/>
      </geometry>
    </visual>
    <collision>
      <geometry>
        <mesh filename="meshes/dg5f_left/ll_dg_mount_c.STL"/>
      </geometry>
    </collision>
  </link>
  <link name="ll_dg_base">
    <inertial>
      <origin xyz="-0.00058969 -0.00051381 0.037363" rpy="0.0 0.0 0.0"/>
      <inertia ixx="0.00048608" ixy="-1.041E-05" ixz="1.7229E-05" iyy="0.00049085" iyz="5.191E-06" izz="0.00043369"/>
      <mass value="0.3529"/>
    </inertial>
    <visual>
      <origin xyz="0 0 0" rpy="0 0 0"/>
      <geometry>
        <mesh filename="meshes/dg5f_left/ll_dg_base.dae"/>
      </geometry>
    </visual>
    <collision>
      <origin xyz="0 0 0" rpy="0 0 0"/>
      <geometry>
        <mesh filename="meshes/dg5f_left/ll_dg_base_c.STL"/>
      </geometry>
    </collision>
  </link>
  <joint name="lj_dg_base" type="fixed">
    <parent link="ll_dg_mount"/>
    <child link="ll_dg_base"/>
    <origin rpy="0 0 0" xyz="0 0 0.004"/>
  </joint>
  <link name="ll_dg_palm">
    <inertial>
      <origin xyz="-0.0089544 -0.00095674 0.041327" rpy="0.0 0.0 0.0"/>
      <inertia ixx="0.00052648" ixy="-2.618E-06" ixz="-2.2256E-05" iyy="0.00041644" iyz="4.8923E-05" izz="0.00045776"/>
      <mass value="0.5578"/>
    </inertial>
    <visual>
      <origin xyz="0 0 0" rpy="0 0 0"/>
      <geometry>
        <mesh filename="meshes/dg5f_left/ll_dg_palm.dae"/>
      </geometry>
    </visual>
    <collision>
      <origin xyz="0 0 0" rpy="0 0 0"/>
      <geometry>
        <mesh filename="meshes/dg5f_left/ll_dg_palm_c.STL"/>
      </geometry>
    </collision>
  </link>
  <joint name="lj_dg_palm" type="fixed">
    <parent link="ll_dg_base"/>
    <child link="ll_dg_palm"/>
    <origin rpy="0 0 0" xyz="0 0 0.0698"/>
  </joint>
  <link name="ll_dg_1_1">
    <inertial>
      <origin xyz="0.021473 3.1163E-06 0.0028146" rpy="0.0 0.0 0.0"/>
      <inertia ixx="4.2707E-06" ixy="2.4123E-09" ixz="2.9055E-06" iyy="1.3718E-05" iyz="-1.3824E-09" izz="1.2161E-05"/>
      <mass value="0.0482"/>
    </inertial>
    <visual>
      <origin xyz="0 0 0" rpy="0 0 0"/>
      <geometry>
        <mesh filename="meshes/dg5f_left/ll_dg_1_1.dae"/>
      </geometry>
    </visual>
    <collision>
      <origin xyz="0 0 0" rpy="0 0 0"/>
      <geometry>
        <mesh filename="meshes/dg5f_left/ll_dg_1_1_c.STL"/>
      </geometry>
    </collision>
  </link>
  <joint name="lj_dg_1_1" type="revolute">
    <origin xyz="-0.0162 -0.019 0.0128" rpy="0.0 0.0 0.0"/>
    <parent link="ll_dg_palm"/>
    <child link="ll_dg_1_1"/>
    <axis xyz="1 0 0"/>
    <limit lower="-1.3439035240356338" upper="0.3839724354387525" effort="7.5" velocity="3.141592653589793"/>
  </joint>
  <link name="ll_dg_1_2">
    <inertial>
      <origin xyz="-0.00055633 -0.0155 0.00055633" rpy="0.0 0.0 0.0"/>
      <inertia ixx="1.9935E-06" ixy="-1.5774E-07" ixz="-3.114E-09" iyy="1.459E-06" iyz="-1.5774E-07" izz="1.9935E-06"/>
      <mass value="0.0164"/>
    </inertial>
    <visual>
      <origin xyz="0 0 0" rpy="0 0 0"/>
      <geometry>
        <mesh filename="meshes/dg5f_left/ll_dg_1_2.dae"/>
      </geometry>
    </visual>
    <collision>
      <origin xyz="0 0 0" rpy="0 0 0"/>
      <geometry>
        <mesh filename="meshes/dg5f_left/ll_dg_1_2_c.STL"/>
      </geometry>
    </collision>
  </link>
  <joint name="lj_dg_1_2" type="revolute">
    <origin xyz="0.04195 0.0 0.0" rpy="0.0 0.0 0.0"/>
    <parent link="ll_dg_1_1"/>
    <child link="ll_dg_1_2"/>
    <axis xyz="0 0 1"/>
    <limit lower="-0.0" upper="2.705260340591211" effort="7.5" velocity="3.141592653589793"/>
  </joint>
  <link name="ll_dg_1_3">
    <inertial>
      <origin xyz="-2.3008E-05 -0.014842 4.7446E-06" rpy="0.0 0.0 0.0"/>
      <inertia ixx="5.9794E-06" ixy="-3.6014E-07" ixz="1.3678E-09" iyy="2.458E-06" iyz="2.3552E-09" izz="6.4181E-06"/>
      <mass value="0.0362"/>
    </inertial>
    <visual>
      <origin xyz="0 0 0" rpy="0 0 0"/>
      <geometry>
        <mesh filename="meshes/dg5f_left/ll_dg_1_3.dae"/>
      </geometry>
    </visual>
    <collision>
      <origin xyz="0 0 0" rpy="0 0 0"/>
      <geometry>
        <mesh filename="meshes/dg5f_left/ll_dg_1_3_c.STL"/>
      </geometry>
    </collision>
  </link>
  <joint name="lj_dg_1_3" type="revolute">
    <origin xyz="0.0 -0.031 0.0" rpy="0.0 0.0 0.0"/>
    <parent link="ll_dg_1_2"/>
    <child link="ll_dg_1_3"/>
    <axis xyz="1 0 0"/>
    <limit lower="-1.5707963267948966" upper="1.5707963267948966" effort="7.5" velocity="3.141592653589793"/>
  </joint>
  <link name="ll_dg_1_4">
    <inertial>
      <origin xyz="0.00020482 -0.018795 -0.00036539" rpy="0.0 0.0 0.0"/>
      <inertia ixx="9.4915E-06" ixy="-1.5157E-07" ixz="-3.4626E-09" iyy="2.9391E-06" iyz="-3.7813E-07" izz="9.8194E-06"/>
      <mass value="0.0505"/>
    </inertial>
    <visual>
      <origin xyz="0 0 0" rpy="0 0 0"/>
      <geometry>
        <mesh filename="meshes/dg5f_left/ll_dg_1_4.dae"/>
      </geometry>
    </visual>
    <collision>
      <origin xyz="0 0 0" rpy="0 0 0"/>
      <geometry>
        <mesh filename="meshes/dg5f_left/ll_dg_1_4_c.STL"/>
      </geometry>
    </collision>
  </link>
  <joint name="lj_dg_1_4" type="revolute">
    <origin xyz="0.0 -0.0388 0.0" rpy="0.0 0.0 0.0"/>
    <parent link="ll_dg_1_3"/>
    <child link="ll_dg_1_4"/>
    <axis xyz="1 0 0"/>
    <limit lower="-1.5707963267948966" upper="1.5707963267948966" effort="7.5" velocity="3.141592653589793"/>
  </joint>
  <link name="ll_dg_1_tip">
    <inertial>
      <origin xyz="-5.479E-07 -0.007157 0.0038063" rpy="0.0 0.0 0.0"/>
      <inertia ixx="1.9895E-07" ixy="-3.0731E-11" ixz="-2.1191E-12" iyy="2.5698E-07" iyz="-1.3375E-08" izz="3.2445E-07"/>
      <mass value="0.005"/>
    </inertial>
    <visual>
      <origin xyz="0 0 0" rpy="0 0 0"/>
      <geometry>
        <mesh filename="meshes/dg5f_left/ll_dg_1_tip.dae"/>
      </geometry>
    </visual>
    <collision>
      <origin xyz="0 0 0" rpy="0 0 0"/>
      <geometry>
        <mesh filename="meshes/dg5f_left/ll_dg_1_tip_c.STL"/>
      </geometry>
    </collision>
  </link>
  <joint name="lj_dg_1_tip" type="fixed">
    <origin xyz="0.0 -0.0363 0.0" rpy="0.0 0.0 0.0"/>
    <parent link="ll_dg_1_4"/>
    <child link="ll_dg_1_tip"/>
  </joint>
  <link name="ll_dg_2_1">
    <inertial>
      <origin xyz="0.0010606 -0.00058566 0.023499" rpy="0.0 0.0 0.0"/>
      <inertia ixx="6.5541E-06" ixy="1.8684E-07" ixz="-1.1508E-06" iyy="9.5306E-06" iyz="-5.3298E-09" izz="7.0879E-06"/>
      <mass value="0.0546"/>
    </inertial>
    <visual>
      <origin xyz="0 0 0" rpy="0 0 0"/>
      <geometry>
        <mesh filename="meshes/dg5f_left/ll_dg_2_1.dae"/>
      </geometry>
    </visual>
    <collision>
      <origin xyz="0 0 0" rpy="0 0 0"/>
      <geometry>
        <mesh filename="meshes/dg5f_left/ll_dg_2_1_c.STL"/>
      </geometry>
    </collision>
  </link>
  <joint name="lj_dg_2_1" type="revolute">
    <origin xyz="-0.0071 -0.027 0.0661" rpy="0.0 0.0 0.0"/>
    <parent link="ll_dg_palm"/>
    <child link="ll_dg_2_1"/>
    <axis xyz="1 0 0"/>
    <limit lower="-0.3490658503988659" upper="0.5410520681182421" effort="7.5" velocity="3.141592653589793"/>
  </joint>
  <link name="ll_dg_2_2">
    <inertial>
      <origin xyz="-4.7446E-06 2.3008E-05 0.023958" rpy="0.0 0.0 0.0"/>
      <inertia ixx="6.4181E-06" ixy="1.3678E-09" ixz="-2.3552E-09" iyy="5.9794E-06" iyz="3.6014E-07" izz="2.458E-06"/>
      <mass value="0.0362"/>
    </inertial>
    <visual>
      <origin xyz="0 0 0" rpy="0 0 0"/>
      <geometry>
        <mesh filename="meshes/dg5f_left/ll_dg_2_2.dae"/>
      </geometry>
    </visual>
    <collision>
      <origin xyz="0 0 0" rpy="0 0 0"/>
      <geometry>
        <mesh filename="meshes/dg5f_left/ll_dg_2_2_c.STL"/>
      </geometry>
    </collision>
  </link>
  <joint name="lj_dg_2_2" type="revolute">
    <origin xyz="0.01765 0.0 0.0265" rpy="0.0 0.0 0.0"/>
    <parent link="ll_dg_2_1"/>
    <child link="ll_dg_2_2"/>
    <axis xyz="0 1 0"/>
    <limit lower="-0.0" upper="2.007128639793479" effort="7.5" velocity="3.141592653589793"/>
  </joint>
  <link name="ll_dg_2_3">
    <inertial>
      <origin xyz="-4.7446E-06 2.3008E-05 0.023958" rpy="0.0 0.0 0.0"/>
      <inertia ixx="6.4181E-06" ixy="1.3678E-09" ixz="-2.3552E-09" iyy="5.9794E-06" iyz="3.6014E-07" izz="2.458E-06"/>
      <mass value="0.0362"/>
    </inertial>
    <visual>
      <origin xyz="0 0 0" rpy="0 0 0"/>
      <geometry>
        <mesh filename="meshes/dg5f_left/ll_dg_2_3.dae"/>
      </geometry>
    </visual>
    <collision>
      <origin xyz="0 0 0" rpy="0 0 0"/>
      <geometry>
        <mesh filename="meshes/dg5f_left/ll_dg_2_3_c.STL"/>
      </geometry>
    </collision>
  </link>
  <joint name="lj_dg_2_3" type="revolute">
    <origin xyz="0.0 0.0 0.0388" rpy="0.0 0.0 0.0"/>
    <parent link="ll_dg_2_2"/>
    <child link="ll_dg_2_3"/>
    <axis xyz="0 1 0"/>
    <limit lower="-1.5707963267948966" upper="1.5707963267948966" effort="7.5" velocity="3.141592653589793"/>
  </joint>
  <link name="ll_dg_2_4">
    <inertial>
      <origin xyz="-0.00070816 0.00043036 0.017842" rpy="0.0 0.0 0.0"/>
      <inertia ixx="2.8592E-06" ixy="-5.9306E-09" ixz="2.1028E-07" iyy="2.3907E-06" iyz="1.8286E-07" izz="1.6592E-06"/>
      <mass value="0.0266"/>
    </inertial>
    <visual>
      <origin xyz="0 0 0" rpy="0 0 0"/>
      <geometry>
        <mesh filename="meshes/dg5f_left/ll_dg_2_4.dae"/>
      </geometry>
    </visual>
    <collision>
      <origin xyz="0 0 0" rpy="0 0 0"/>
      <geometry>
        <mesh filename="meshes/dg5f_left/ll_dg_2_4_c.STL"/>
      </geometry>
    </collision>
  </link>
  <joint name="lj_dg_2_4" type="revolute">
    <origin xyz="0.0 0.0 0.0388" rpy="0.0 0.0 0.0"/>
    <parent link="ll_dg_2_3"/>
    <child link="ll_dg_2_4"/>
    <axis xyz="0 1 0"/>
    <limit lower="-1.5707963267948966" upper="1.5707963267948966" effort="7.5" velocity="3.141592653589793"/>
  </joint>
  <link name="ll_dg_2_tip">
    <inertial>
      <origin xyz="0.0038063 5.479E-07 0.007157" rpy="0.0 0.0 0.0"/>
      <inertia ixx="3.2445E-07" ixy="2.1191E-12" ixz="1.3375E-08" iyy="1.9895E-07" iyz="-3.0731E-11" izz="2.5698E-07"/>
      <mass value="0.005"/>
    </inertial>
    <visual>
      <origin xyz="0 0 0" rpy="0 0 0"/>
      <geometry>
        <mesh filename="meshes/dg5f_left/ll_dg_2_tip.dae"/>
      </geometry>
    </visual>
    <collision>
      <origin xyz="0 0 0" rpy="0 0 0"/>
      <geometry>
        <mesh filename="meshes/dg5f_left/ll_dg_2_tip_c.STL"/>
      </geometry>
    </collision>
  </link>
  <joint name="lj_dg_2_tip" type="fixed">
    <origin xyz="0.0 0.0 0.0255" rpy="0.0 0.0 0.0"/>
    <parent link="ll_dg_2_4"/>
    <child link="ll_dg_2_tip"/>
  </joint>
  <link name="ll_dg_3_1">
    <inertial>
      <origin xyz="0.0012558 -0.00017703 0.023374" rpy="0.0 0.0 0.0"/>
      <inertia ixx="6.233E-06" ixy="1.1315E-07" ixz="-1.1589E-06" iyy="9.3331E-06" iyz="3.5383E-08" izz="6.7817E-06"/>
      <mass value="0.0526"/>
    </inertial>
    <visual>
      <origin xyz="0 0 0" rpy="0 0 0"/>
      <geometry>
        <mesh filename="meshes/dg5f_left/ll_dg_3_1.dae"/>
      </geometry>
    </visual>
    <collision>
      <origin xyz="0 0 0" rpy="0 0 0"/>
      <geometry>
        <mesh filename="meshes/dg5f_left/ll_dg_3_1_c.STL"/>
      </geometry>
    </collision>
  </link>
  <joint name="lj_dg_3_1" type="revolute">
    <origin xyz="-0.0071 -0.0025 0.0701" rpy="0.0 0.0 0.0"/>
    <parent link="ll_dg_palm"/>
    <child link="ll_dg_3_1"/>
    <axis xyz="1 0 0"/>
    <limit lower="-0.4363323129985824" upper="0.4363323129985824" effort="7.5" velocity="3.141592653589793"/>
  </joint>
  <link name="ll_dg_3_2">
    <inertial>
      <origin xyz="-4.7446E-06 2.3008E-05 0.023958" rpy="0.0 0.0 0.0"/>
      <inertia ixx="6.4181E-06" ixy="1.3678E-09" ixz="-2.3552E-09" iyy="5.9794E-06" iyz="3.6014E-07" izz="2.458E-06"/>
      <mass value="0.0362"/>
    </inertial>
    <visual>
      <origin xyz="0 0 0" rpy="0 0 0"/>
      <geometry>
        <mesh filename="meshes/dg5f_left/ll_dg_3_2.dae"/>
      </geometry>
    </visual>
    <collision>
      <origin xyz="0 0 0" rpy="0 0 0"/>
      <geometry>
        <mesh filename="meshes/dg5f_left/ll_dg_3_2_c.STL"/>
      </geometry>
    </collision>
  </link>
  <joint name="lj_dg_3_2" type="revolute">
    <origin xyz="0.01765 0.0 0.0265" rpy="0.0 0.0 0.0"/>
    <parent link="ll_dg_3_1"/>
    <child link="ll_dg_3_2"/>
    <axis xyz="0 1 0"/>
    <limit lower="0.0" upper="2.007128639793479" effort="7.5" velocity="3.141592653589793"/>
  </joint>
  <link name="ll_dg_3_3">
    <inertial>
      <origin xyz="-4.7446E-06 2.3008E-05 0.023958" rpy="0.0 0.0 0.0"/>
      <inertia ixx="6.4181E-06" ixy="1.3678E-09" ixz="-2.3552E-09" iyy="5.9794E-06" iyz="3.6014E-07" izz="2.458E-06"/>
      <mass value="0.0362"/>
    </inertial>
    <visual>
      <origin xyz="0 0 0" rpy="0 0 0"/>
      <geometry>
        <mesh filename="meshes/dg5f_left/ll_dg_3_3.dae"/>
      </geometry>
    </visual>
    <collision>
      <origin xyz="0 0 0" rpy="0 0 0"/>
      <geometry>
        <mesh filename="meshes/dg5f_left/ll_dg_3_3_c.STL"/>
      </geometry>
    </collision>
  </link>
  <joint name="lj_dg_3_3" type="revolute">
    <origin xyz="0.0 0.0 0.0388" rpy="0.0 0.0 0.0"/>
    <parent link="ll_dg_3_2"/>
    <child link="ll_dg_3_3"/>
    <axis xyz="0 1 0"/>
    <limit lower="-1.5707963267948966" upper="1.5707963267948966" effort="7.5" velocity="3.141592653589793"/>
  </joint>
  <link name="ll_dg_3_4">
    <inertial>
      <origin xyz="-0.00070816 0.00043036 0.017842" rpy="0.0 0.0 0.0"/>
      <inertia ixx="2.8592E-06" ixy="-5.9306E-09" ixz="2.1028E-07" iyy="2.3907E-06" iyz="1.8286E-07" izz="1.6592E-06"/>
      <mass value="0.0266"/>
    </inertial>
    <visual>
      <origin xyz="0 0 0" rpy="0 0 0"/>
      <geometry>
        <mesh filename="meshes/dg5f_left/ll_dg_3_4.dae"/>
      </geometry>
    </visual>
    <collision>
      <origin xyz="0 0 0" rpy="0 0 0"/>
      <geometry>
        <mesh filename="meshes/dg5f_left/ll_dg_3_4_c.STL"/>
      </geometry>
    </collision>
  </link>
  <joint name="lj_dg_3_4" type="revolute">
    <origin xyz="0.0 0.0 0.0388" rpy="0.0 0.0 0.0"/>
    <parent link="ll_dg_3_3"/>
    <child link="ll_dg_3_4"/>
    <axis xyz="0 1 0"/>
    <limit lower="-1.5707963267948966" upper="1.5707963267948966" effort="7.5" velocity="3.141592653589793"/>
  </joint>
  <link name="ll_dg_3_tip">
    <inertial>
      <origin xyz="0.0038063 5.479E-07 0.007157" rpy="0.0 0.0 0.0"/>
      <inertia ixx="3.2445E-07" ixy="2.1191E-12" ixz="1.3375E-08" iyy="1.9895E-07" iyz="-3.0731E-11" izz="2.5698E-07"/>
      <mass value="0.005"/>
    </inertial>
    <visual>
      <origin xyz="0 0 0" rpy="0 0 0"/>
      <geometry>
        <mesh filename="meshes/dg5f_left/ll_dg_3_tip.dae"/>
      </geometry>
    </visual>
    <collision>
      <origin xyz="0 0 0" rpy="0 0 0"/>
      <geometry>
        <mesh filename="meshes/dg5f_left/ll_dg_3_tip_c.STL"/>
      </geometry>
    </collision>
  </link>
  <joint name="lj_dg_3_tip" type="fixed">
    <origin xyz="0.0 0.0 0.0255" rpy="0.0 0.0 0.0"/>
    <parent link="ll_dg_3_4"/>
    <child link="ll_dg_3_tip"/>
  </joint>
  <link name="ll_dg_4_1">
    <inertial>
      <origin xyz="0.001061 0.00024417 0.023499" rpy="0.0 0.0 0.0"/>
      <inertia ixx="6.5538E-06" ixy="3.9294E-08" ixz="-1.1507E-06" iyy="9.5305E-06" iyz="7.6072E-08" izz="7.0877E-06"/>
      <mass value="0.0548"/>
    </inertial>
    <visual>
      <origin xyz="0 0 0" rpy="0 0 0"/>
      <geometry>
        <mesh filename="meshes/dg5f_left/ll_dg_4_1.dae"/>
      </geometry>
    </visual>
    <collision>
      <origin xyz="0 0 0" rpy="0 0 0"/>
      <geometry>
        <mesh filename="meshes/dg5f_left/ll_dg_4_1_c.STL"/>
      </geometry>
    </collision>
  </link>
  <joint name="lj_dg_4_1" type="revolute">
    <origin xyz="-0.0071 0.022 0.0621" rpy="0.0 0.0 0.0"/>
    <parent link="ll_dg_palm"/>
    <child link="ll_dg_4_1"/>
    <axis xyz="1 0 0"/>
    <limit lower="-0.5585053606381855" upper="0.2617993877991494" effort="7.5" velocity="3.141592653589793"/>
  </joint>
  <link name="ll_dg_4_2">
    <inertial>
      <origin xyz="-4.7446E-06 2.3008E-05 0.023958" rpy="0.0 0.0 0.0"/>
      <inertia ixx="6.4181E-06" ixy="1.3678E-09" ixz="-2.3552E-09" iyy="5.9794E-06" iyz="3.6014E-07" izz="2.458E-06"/>
      <mass value="0.0362"/>
    </inertial>
    <visual>
      <origin xyz="0 0 0" rpy="0 0 0"/>
      <geometry>
        <mesh filename="meshes/dg5f_left/ll_dg_4_2.dae"/>
      </geometry>
    </visual>
    <collision>
      <origin xyz="0 0 0" rpy="0 0 0"/>
      <geometry>
        <mesh filename="meshes/dg5f_left/ll_dg_4_2_c.STL"/>
      </geometry>
    </collision>
  </link>
  <joint name="lj_dg_4_2" type="revolute">
    <origin xyz="0.01765 0.0 0.0265" rpy="0.0 0.0 0.0"/>
    <parent link="ll_dg_4_1"/>
    <child link="ll_dg_4_2"/>
    <axis xyz="0 1 0"/>
    <limit lower="0.0" upper="1.9198621771937625" effort="7.5" velocity="3.141592653589793"/>
  </joint>
  <link name="ll_dg_4_3">
    <inertial>
      <origin xyz="-4.7446E-06 2.3008E-05 0.023958" rpy="0.0 0.0 0.0"/>
      <inertia ixx="6.4181E-06" ixy="1.3678E-09" ixz="-2.3552E-09" iyy="5.9794E-06" iyz="3.6014E-07" izz="2.458E-06"/>
      <mass value="0.0362"/>
    </inertial>
    <visual>
      <origin xyz="0 0 0" rpy="0 0 0"/>
      <geometry>
        <mesh filename="meshes/dg5f_left/ll_dg_4_3.dae"/>
      </geometry>
    </visual>
    <collision>
      <origin xyz="0 0 0" rpy="0 0 0"/>
      <geometry>
        <mesh filename="meshes/dg5f_left/ll_dg_4_3_c.STL"/>
      </geometry>
    </collision>
  </link>
  <joint name="lj_dg_4_3" type="revolute">
    <origin xyz="0.0 0.0 0.0388" rpy="0.0 0.0 0.0"/>
    <parent link="ll_dg_4_2"/>
    <child link="ll_dg_4_3"/>
    <axis xyz="0 1 0"/>
    <limit lower="-1.5707963267948966" upper="1.5707963267948966" effort="7.5" velocity="3.141592653589793"/>
  </joint>
  <link name="ll_dg_4_4">
    <inertial>
      <origin xyz="-0.00070816 0.00043036 0.017842" rpy="0.0 0.0 0.0"/>
      <inertia ixx="2.8592E-06" ixy="-5.9306E-09" ixz="2.1028E-07" iyy="2.3907E-06" iyz="1.8286E-07" izz="1.6592E-06"/>
      <mass value="0.0266"/>
    </inertial>
    <visual>
      <origin xyz="0 0 0" rpy="0 0 0"/>
      <geometry>
        <mesh filename="meshes/dg5f_left/ll_dg_4_4.dae"/>
      </geometry>
    </visual>
    <collision>
      <origin xyz="0 0 0" rpy="0 0 0"/>
      <geometry>
        <mesh filename="meshes/dg5f_left/ll_dg_4_4_c.STL"/>
      </geometry>
    </collision>
  </link>
  <joint name="lj_dg_4_4" type="revolute">
    <origin xyz="0.0 0.0 0.0388" rpy="0.0 0.0 0.0"/>
    <parent link="ll_dg_4_3"/>
    <child link="ll_dg_4_4"/>
    <axis xyz="0 1 0"/>
    <limit lower="-1.5707963267948966" upper="1.5707963267948966" effort="7.5" velocity="3.141592653589793"/>
  </joint>
  <link name="ll_dg_4_tip">
    <inertial>
      <origin xyz="0.0038063 5.479E-07 0.007157" rpy="0.0 0.0 0.0"/>
      <inertia ixx="3.2445E-07" ixy="2.1191E-12" ixz="1.3375E-08" iyy="1.9895E-07" iyz="-3.0731E-11" izz="2.5698E-07"/>
      <mass value="0.005"/>
    </inertial>
    <visual>
      <origin xyz="0 0 0" rpy="0 0 0"/>
      <geometry>
        <mesh filename="meshes/dg5f_left/ll_dg_4_tip.dae"/>
      </geometry>
    </visual>
    <collision>
      <origin xyz="0 0 0" rpy="0 0 0"/>
      <geometry>
        <mesh filename="meshes/dg5f_left/ll_dg_4_tip_c.STL"/>
      </geometry>
    </collision>
  </link>
  <joint name="lj_dg_4_tip" type="fixed">
    <origin xyz="0.0 0.0 0.0255" rpy="0.0 0.0 0.0"/>
    <parent link="ll_dg_4_4"/>
    <child link="ll_dg_4_tip"/>
  </joint>
  <link name="ll_dg_5_1">
    <inertial>
      <origin xyz="-0.0045287 0.025016 0.014025" rpy="0.0 0.0 0.0"/>
      <inertia ixx="2.3621E-05" ixy="-2.0571E-07" ixz="2.5894E-06" iyy="2.3655E-05" iyz="-4.4786E-06" izz="1.1298E-05"/>
      <mass value="0.0744"/>
    </inertial>
    <visual>
      <origin xyz="0 0 0" rpy="0 0 0"/>
      <geometry>
        <mesh filename="meshes/dg5f_left/ll_dg_5_1.dae"/>
      </geometry>
    </visual>
    <collision>
      <origin xyz="0 0 0" rpy="0 0 0"/>
      <geometry>
        <mesh filename="meshes/dg5f_left/ll_dg_5_1_c.STL"/>
      </geometry>
    </collision>
  </link>
  <joint name="lj_dg_5_1" type="revolute">
    <origin xyz="0.0103 0.0195 0.0182" rpy="0.0 0.0 0.0"/>
    <parent link="ll_dg_palm"/>
    <child link="ll_dg_5_1"/>
    <axis xyz="0 0 1"/>
    <limit lower="-1.0471975511965976" upper="0.0" effort="7.5" velocity="3.141592653589793"/>
  </joint>
  <link name="ll_dg_5_2">
    <inertial>
      <origin xyz="0.00055633 0.00055633 0.0155" rpy="0.0 0.0 0.0"/>
      <inertia ixx="1.9935E-06" ixy="3.114E-09" ixz="1.5774E-07" iyy="1.9935E-06" iyz="-1.5774E-07" izz="1.459E-06"/>
      <mass value="0.0164"/>
    </inertial>
    <visual>
      <origin xyz="0 0 0" rpy="0 0 0"/>
      <geometry>
        <mesh filename="meshes/dg5f_left/ll_dg_5_2.dae"/>
      </geometry>
    </visual>
    <collision>
      <origin xyz="0 0 0" rpy="0 0 0"/>
      <geometry>
        <mesh filename="meshes/dg5f_left/ll_dg_5_2_c.STL"/>
      </geometry>
    </collision>
  </link>
  <joint name="lj_dg_5_2" type="revolute">
    <origin xyz="0.0 0.028 0.0381" rpy="0.0 0.0 0.0"/>
    <parent link="ll_dg_5_1"/>
    <child link="ll_dg_5_2"/>
    <axis xyz="1 0 0"/>
    <limit lower="-1.5707963267948966" upper="0.2617993877991494" effort="7.5" velocity="3.141592653589793"/>
  </joint>
  <link name="ll_dg_5_3">
    <inertial>
      <origin xyz="4.7446E-06 2.3008E-05 0.014842" rpy="0.0 0.0 0.0"/>
      <inertia ixx="6.4181E-06" ixy="-1.3678E-09" ixz="-2.3552E-09" iyy="5.9794E-06" iyz="-3.6014E-07" izz="2.458E-06"/>
      <mass value="0.0362"/>
    </inertial>
    <visual>
      <origin xyz="0 0 0" rpy="0 0 0"/>
      <geometry>
        <mesh filename="meshes/dg5f_left/ll_dg_5_3.dae"/>
      </geometry>
    </visual>
    <collision>
      <origin xyz="0 0 0" rpy="0 0 0"/>
      <geometry>
        <mesh filename="meshes/dg5f_left/ll_dg_5_3_c.STL"/>
      </geometry>
    </collision>
  </link>
  <joint name="lj_dg_5_3" type="revolute">
    <origin xyz="0.0 0.0 0.031" rpy="0.0 0.0 0.0"/>
    <parent link="ll_dg_5_2"/>
    <child link="ll_dg_5_3"/>
    <axis xyz="0 1 0"/>
    <limit lower="-1.5707963267948966" upper="1.5707963267948966" effort="7.5" velocity="3.141592653589793"/>
  </joint>
  <link name="ll_dg_5_4">
    <inertial>
      <origin xyz="-0.00036539 -0.00020482 0.018795" rpy="0.0 0.0 0.0"/>
      <inertia ixx="9.8194E-06" ixy="3.4626E-09" ixz="3.7813E-07" iyy="9.4915E-06" iyz="-1.5157E-07" izz="2.9391E-06"/>
      <mass value="0.0505"/>
    </inertial>
    <visual>
      <origin xyz="0 0 0" rpy="0 0 0"/>
      <geometry>
        <mesh filename="meshes/dg5f_left/ll_dg_5_4.dae"/>
      </geometry>
    </visual>
    <collision>
      <origin xyz="0 0 0" rpy="0 0 0"/>
      <geometry>
        <mesh filename="meshes/dg5f_left/ll_dg_5_4_c.STL"/>
      </geometry>
    </collision>
  </link>
  <joint name="lj_dg_5_4" type="revolute">
    <origin xyz="0.0 0.0 0.0388" rpy="0.0 0.0 0.0"/>
    <parent link="ll_dg_5_3"/>
    <child link="ll_dg_5_4"/>
    <axis xyz="0 1 0"/>
    <limit lower="-1.5707963267948966" upper="1.5707963267948966" effort="7.5" velocity="3.141592653589793"/>
  </joint>
  <link name="ll_dg_5_tip">
    <inertial>
      <origin xyz="0.0038063 5.479E-07 0.007157" rpy="0.0 0.0 0.0"/>
      <inertia ixx="3.2445E-07" ixy="2.1191E-12" ixz="1.3375E-08" iyy="1.9895E-07" iyz="-3.0731E-11" izz="2.5698E-07"/>
      <mass value="0.005"/>
    </inertial>
    <visual>
      <origin xyz="0 0 0" rpy="0 0 0"/>
      <geometry>
        <mesh filename="meshes/dg5f_left/ll_dg_5_tip.dae"/>
      </geometry>
    </visual>
    <collision>
      <origin xyz="0 0 0" rpy="0 0 0"/>
      <geometry>
        <mesh filename="meshes/dg5f_left/ll_dg_5_tip_c.STL"/>
      </geometry>
    </collision>
  </link>
  <joint name="lj_dg_5_tip" type="fixed">
    <origin xyz="0.0 0.0 0.0363" rpy="0.0 0.0 0.0"/>
    <parent link="ll_dg_5_4"/>
    <child link="ll_dg_5_tip"/>
  </joint>
  <joint name="tool0_to_dg_mount" type="fixed">
    <parent link="tool0"/>
    <child link="ll_dg_mount"/>
    <origin xyz="0 0 0" rpy="0 0 0"/>
  </joint>
</robot>
